```
(venv) F:\Django\Access>python manage.py createsuperuser
Traceback (most recent call last):
  File "manage.py", line 22, in <module>
    execute_from_command_line(sys.argv)
  File "F:\venv\lib\site-packages\django\core\management\__init__.py", line 364, in execute_from_command_line
    utility.execute()
  File "F:\venv\lib\site-packages\django\core\management\__init__.py", line 338, in execute
    django.setup()
  File "F:\venv\lib\site-packages\django\__init__.py", line 27, in setup
    apps.populate(settings.INSTALLED_APPS)
  File "F:\venv\lib\site-packages\django\apps\registry.py", line 108, in populate
    app_config.import_models()
  File "F:\venv\lib\site-packages\django\apps\config.py", line 202, in import_models
    self.models_module = import_module(models_module_name)
  File "F:\venv\lib\importlib\__init__.py", line 126, in import_module
    return _bootstrap._gcd_import(name[level:], package, level)
  File "<frozen importlib._bootstrap>", line 994, in _gcd_import
  File "<frozen importlib._bootstrap>", line 971, in _find_and_load
  File "<frozen importlib._bootstrap>", line 955, in _find_and_load_unlocked
  File "<frozen importlib._bootstrap>", line 665, in _load_unlocked
  File "<frozen importlib._bootstrap_external>", line 678, in exec_module
  File "<frozen importlib._bootstrap>", line 219, in _call_with_frames_removed
  File "F:\Django\Access\rbac\models.py", line 13, in <module>
    class Permission(models.Model):
  File "F:\Django\Access\rbac\models.py", line 18, in Permission
    PermissionMenu = models.ManyToOneRel(to='Menu')
TypeError: __init__() missing 2 required positional arguments: 'field' and 'field_name'

(venv) F:\Django\Access>python manage.py createsuperuser

You have 13 unapplied migration(s). Your project may not work properly until you apply the migrations for app(s): admin, auth, contenttypes, sessions.
Run 'python manage.py migrate' to apply them.
Traceback (most recent call last):
  File "F:\venv\lib\site-packages\django\db\backends\utils.py", line 64, in execute
    return self.cursor.execute(sql, params)
  File "F:\venv\lib\site-packages\django\db\backends\sqlite3\base.py", line 328, in execute
    return Database.Cursor.execute(self, query, params)
sqlite3.OperationalError: no such table: auth_user

The above exception was the direct cause of the following exception:

Traceback (most recent call last):
  File "manage.py", line 22, in <module>
    execute_from_command_line(sys.argv)
  File "F:\venv\lib\site-packages\django\core\management\__init__.py", line 364, in execute_from_command_line
    utility.execute()
  File "F:\venv\lib\site-packages\django\core\management\__init__.py", line 356, in execute
    self.fetch_command(subcommand).run_from_argv(self.argv)
  File "F:\venv\lib\site-packages\django\core\management\base.py", line 283, in run_from_argv
    self.execute(*args, **cmd_options)
  File "F:\venv\lib\site-packages\django\contrib\auth\management\commands\createsuperuser.py", line 63, in execute
    return super(Command, self).execute(*args, **options)
  File "F:\venv\lib\site-packages\django\core\management\base.py", line 330, in execute
    output = self.handle(*args, **options)
  File "F:\venv\lib\site-packages\django\contrib\auth\management\commands\createsuperuser.py", line 96, in handle
    default_username = get_default_username()
  File "F:\venv\lib\site-packages\django\contrib\auth\management\__init__.py", line 148, in get_default_username
    auth_app.User._default_manager.get(username=default_username)
  File "F:\venv\lib\site-packages\django\db\models\manager.py", line 85, in manager_method
    return getattr(self.get_queryset(), name)(*args, **kwargs)
  File "F:\venv\lib\site-packages\django\db\models\query.py", line 374, in get
    num = len(clone)
  File "F:\venv\lib\site-packages\django\db\models\query.py", line 232, in __len__
    self._fetch_all()
  File "F:\venv\lib\site-packages\django\db\models\query.py", line 1118, in _fetch_all
    self._result_cache = list(self._iterable_class(self))
  File "F:\venv\lib\site-packages\django\db\models\query.py", line 53, in __iter__
    results = compiler.execute_sql(chunked_fetch=self.chunked_fetch)
  File "F:\venv\lib\site-packages\django\db\models\sql\compiler.py", line 899, in execute_sql
    raise original_exception
  File "F:\venv\lib\site-packages\django\db\models\sql\compiler.py", line 889, in execute_sql
    cursor.execute(sql, params)
  File "F:\venv\lib\site-packages\django\db\backends\utils.py", line 79, in execute
    return super(CursorDebugWrapper, self).execute(sql, params)
  File "F:\venv\lib\site-packages\django\db\backends\utils.py", line 64, in execute
    return self.cursor.execute(sql, params)
  File "F:\venv\lib\site-packages\django\db\utils.py", line 94, in __exit__
    six.reraise(dj_exc_type, dj_exc_value, traceback)
  File "F:\venv\lib\site-packages\django\utils\six.py", line 685, in reraise
    raise value.with_traceback(tb)
  File "F:\venv\lib\site-packages\django\db\backends\utils.py", line 64, in execute
    return self.cursor.execute(sql, params)
  File "F:\venv\lib\site-packages\django\db\backends\sqlite3\base.py", line 328, in execute
    return Database.Cursor.execute(self, query, params)
django.db.utils.OperationalError: no such table: auth_user

(venv) F:\Django\Access>python manage.py makemigrations
Migrations for 'rbac':
  rbac\migrations\0001_initial.py
    - Create model Menu
    - Create model Permission
    - Create model Role
    - Create model UserInfo
    - Add field PermissionRole to permission

(venv) F:\Django\Access>python manage.py makemigrations
Did you rename permission.PermissionMenu to permission.permissionMenu (a ForeignKey)? [y/N] y
Did you rename permission.PermissionRole to permission.permissionRole (a ManyToManyField)? [y/N] y
Did you rename userinfo.UserRole to userinfo.userRole (a ManyToManyField)? [y/N] y
Migrations for 'rbac':
  rbac\migrations\0002_auto_20181107_1214.py
    - Rename field PermissionMenu on permission to permissionMenu
    - Rename field PermissionRole on permission to permissionRole
    - Rename field UserRole on userinfo to userRole

(venv) F:\Django\Access>python manage.py migrate
Operations to perform:
  Apply all migrations: admin, auth, contenttypes, rbac, sessions
Running migrations:
  Applying contenttypes.0001_initial... OK
  Applying auth.0001_initial... OK
  Applying admin.0001_initial... OK
  Applying admin.0002_logentry_remove_auto_add... OK
  Applying contenttypes.0002_remove_content_type_name... OK
  Applying auth.0002_alter_permission_name_max_length... OK
  Applying auth.0003_alter_user_email_max_length... OK
  Applying auth.0004_alter_user_username_opts... OK
  Applying auth.0005_alter_user_last_login_null... OK
  Applying auth.0006_require_contenttypes_0002... OK
  Applying auth.0007_alter_validators_add_error_messages... OK
  Applying auth.0008_alter_user_username_max_length... OK
  Applying rbac.0001_initial... OK
  Applying rbac.0002_auto_20181107_1214...Traceback (most recent call last):
  File "F:\venv\lib\site-packages\django\db\backends\utils.py", line 62, in execute
    return self.cursor.execute(sql)
  File "F:\venv\lib\site-packages\django\db\backends\sqlite3\base.py", line 326, in execute
    return Database.Cursor.execute(self, query)
sqlite3.OperationalError: table "rbac_permission_permissionRole" already exists

The above exception was the direct cause of the following exception:

Traceback (most recent call last):
  File "manage.py", line 22, in <module>
    execute_from_command_line(sys.argv)
  File "F:\venv\lib\site-packages\django\core\management\__init__.py", line 364, in execute_from_command_line
    utility.execute()
  File "F:\venv\lib\site-packages\django\core\management\__init__.py", line 356, in execute
    self.fetch_command(subcommand).run_from_argv(self.argv)
  File "F:\venv\lib\site-packages\django\core\management\base.py", line 283, in run_from_argv
    self.execute(*args, **cmd_options)
  File "F:\venv\lib\site-packages\django\core\management\base.py", line 330, in execute
    output = self.handle(*args, **options)
  File "F:\venv\lib\site-packages\django\core\management\commands\migrate.py", line 204, in handle
    fake_initial=fake_initial,
  File "F:\venv\lib\site-packages\django\db\migrations\executor.py", line 115, in migrate
    state = self._migrate_all_forwards(state, plan, full_plan, fake=fake, fake_initial=fake_initial)
  File "F:\venv\lib\site-packages\django\db\migrations\executor.py", line 145, in _migrate_all_forwards
    state = self.apply_migration(state, migration, fake=fake, fake_initial=fake_initial)
  File "F:\venv\lib\site-packages\django\db\migrations\executor.py", line 244, in apply_migration
    state = migration.apply(state, schema_editor)
  File "F:\venv\lib\site-packages\django\db\migrations\migration.py", line 129, in apply
    operation.database_forwards(self.app_label, schema_editor, old_state, project_state)
  File "F:\venv\lib\site-packages\django\db\migrations\operations\fields.py", line 311, in database_forwards
    to_model._meta.get_field(self.new_name),
  File "F:\venv\lib\site-packages\django\db\backends\base\schema.py", line 516, in alter_field
    return self._alter_many_to_many(model, old_field, new_field, strict)
  File "F:\venv\lib\site-packages\django\db\backends\sqlite3\schema.py", line 282, in _alter_many_to_many
    self.create_model(new_field.remote_field.through)
  File "F:\venv\lib\site-packages\django\db\backends\base\schema.py", line 319, in create_model
    self.execute(sql, params or None)
  File "F:\venv\lib\site-packages\django\db\backends\base\schema.py", line 136, in execute
    cursor.execute(sql, params)
  File "F:\venv\lib\site-packages\django\db\backends\utils.py", line 79, in execute
    return super(CursorDebugWrapper, self).execute(sql, params)
  File "F:\venv\lib\site-packages\django\db\backends\utils.py", line 64, in execute
    return self.cursor.execute(sql, params)
  File "F:\venv\lib\site-packages\django\db\utils.py", line 94, in __exit__
    six.reraise(dj_exc_type, dj_exc_value, traceback)
  File "F:\venv\lib\site-packages\django\utils\six.py", line 685, in reraise
    raise value.with_traceback(tb)
  File "F:\venv\lib\site-packages\django\db\backends\utils.py", line 62, in execute
    return self.cursor.execute(sql)
  File "F:\venv\lib\site-packages\django\db\backends\sqlite3\base.py", line 326, in execute
    return Database.Cursor.execute(self, query)
django.db.utils.OperationalError: table "rbac_permission_permissionRole" already exists

(venv) F:\Django\Access>python manage.py createsuperuser

You have 2 unapplied migration(s). Your project may not work properly until you apply the migrations for app(s): rbac, sessions.
Run 'python manage.py migrate' to apply them.
Username (leave blank to use 'missa'): admin
Email address: admin@admin.org
Password:
Password (again):
Superuser created successfully.

(venv) F:\Django\Access>python manage.py runserver
Performing system checks...

System check identified no issues (0 silenced).

You have 2 unapplied migration(s). Your project may not work properly until you apply the migrations for app(s): rbac, sessions.
Run 'python manage.py migrate' to apply them.
November 07, 2018 - 12:18:06
Django version 1.11.15, using settings 'Access.settings'
Starting development server at http://127.0.0.1:8000/
Quit the server with CTRL-BREAK.
[07/Nov/2018 12:18:19] "GET / HTTP/1.1" 200 1716
Not Found: /favicon.ico
[07/Nov/2018 12:18:19] "GET /favicon.ico HTTP/1.1" 404 1962
Internal Server Error: /admin/
Traceback (most recent call last):
  File "F:\venv\lib\site-packages\django\contrib\sessions\backends\base.py", line 202, in _get_session
    return self._session_cache
AttributeError: 'SessionStore' object has no attribute '_session_cache'

During handling of the above exception, another exception occurred:

Traceback (most recent call last):
  File "F:\venv\lib\site-packages\django\db\backends\utils.py", line 64, in execute
    return self.cursor.execute(sql, params)
  File "F:\venv\lib\site-packages\django\db\backends\sqlite3\base.py", line 328, in execute
    return Database.Cursor.execute(self, query, params)
sqlite3.OperationalError: no such table: django_session

The above exception was the direct cause of the following exception:

Traceback (most recent call last):
  File "F:\venv\lib\site-packages\django\core\handlers\exception.py", line 41, in inner
    response = get_response(request)
  File "F:\venv\lib\site-packages\django\core\handlers\base.py", line 187, in _get_response
    response = self.process_exception_by_middleware(e, request)
  File "F:\venv\lib\site-packages\django\core\handlers\base.py", line 185, in _get_response
    response = wrapped_callback(request, *callback_args, **callback_kwargs)
  File "F:\venv\lib\site-packages\django\contrib\admin\sites.py", line 242, in wrapper
    return self.admin_view(view, cacheable)(*args, **kwargs)
  File "F:\venv\lib\site-packages\django\utils\decorators.py", line 149, in _wrapped_view
    response = view_func(request, *args, **kwargs)
  File "F:\venv\lib\site-packages\django\views\decorators\cache.py", line 57, in _wrapped_view_func
    response = view_func(request, *args, **kwargs)
  File "F:\venv\lib\site-packages\django\contrib\admin\sites.py", line 213, in inner
    if not self.has_permission(request):
  File "F:\venv\lib\site-packages\django\contrib\admin\sites.py", line 187, in has_permission
    return request.user.is_active and request.user.is_staff
  File "F:\venv\lib\site-packages\django\utils\functional.py", line 238, in inner
    self._setup()
  File "F:\venv\lib\site-packages\django\utils\functional.py", line 386, in _setup
    self._wrapped = self._setupfunc()
  File "F:\venv\lib\site-packages\django\contrib\auth\middleware.py", line 24, in <lambda>
    request.user = SimpleLazyObject(lambda: get_user(request))
  File "F:\venv\lib\site-packages\django\contrib\auth\middleware.py", line 12, in get_user
    request._cached_user = auth.get_user(request)
  File "F:\venv\lib\site-packages\django\contrib\auth\__init__.py", line 211, in get_user
    user_id = _get_user_session_key(request)
  File "F:\venv\lib\site-packages\django\contrib\auth\__init__.py", line 61, in _get_user_session_key
    return get_user_model()._meta.pk.to_python(request.session[SESSION_KEY])
  File "F:\venv\lib\site-packages\django\contrib\sessions\backends\base.py", line 57, in __getitem__
    return self._session[key]
  File "F:\venv\lib\site-packages\django\contrib\sessions\backends\base.py", line 207, in _get_session
    self._session_cache = self.load()
  File "F:\venv\lib\site-packages\django\contrib\sessions\backends\db.py", line 35, in load
    expire_date__gt=timezone.now()
  File "F:\venv\lib\site-packages\django\db\models\manager.py", line 85, in manager_method
    return getattr(self.get_queryset(), name)(*args, **kwargs)
  File "F:\venv\lib\site-packages\django\db\models\query.py", line 374, in get
    num = len(clone)
  File "F:\venv\lib\site-packages\django\db\models\query.py", line 232, in __len__
    self._fetch_all()
  File "F:\venv\lib\site-packages\django\db\models\query.py", line 1118, in _fetch_all
    self._result_cache = list(self._iterable_class(self))
  File "F:\venv\lib\site-packages\django\db\models\query.py", line 53, in __iter__
    results = compiler.execute_sql(chunked_fetch=self.chunked_fetch)
  File "F:\venv\lib\site-packages\django\db\models\sql\compiler.py", line 899, in execute_sql
    raise original_exception
  File "F:\venv\lib\site-packages\django\db\models\sql\compiler.py", line 889, in execute_sql
    cursor.execute(sql, params)
  File "F:\venv\lib\site-packages\django\db\backends\utils.py", line 79, in execute
    return super(CursorDebugWrapper, self).execute(sql, params)
  File "F:\venv\lib\site-packages\django\db\backends\utils.py", line 64, in execute
    return self.cursor.execute(sql, params)
  File "F:\venv\lib\site-packages\django\db\utils.py", line 94, in __exit__
    six.reraise(dj_exc_type, dj_exc_value, traceback)
  File "F:\venv\lib\site-packages\django\utils\six.py", line 685, in reraise
    raise value.with_traceback(tb)
  File "F:\venv\lib\site-packages\django\db\backends\utils.py", line 64, in execute
    return self.cursor.execute(sql, params)
  File "F:\venv\lib\site-packages\django\db\backends\sqlite3\base.py", line 328, in execute
    return Database.Cursor.execute(self, query, params)
django.db.utils.OperationalError: no such table: django_session
[07/Nov/2018 12:18:26] "GET /admin/ HTTP/1.1" 500 187509
Performing system checks...

System check identified no issues (0 silenced).

You have 2 unapplied migration(s). Your project may not work properly until you apply the migrations for app(s): rbac, sessions.
Run 'python manage.py migrate' to apply them.
November 07, 2018 - 12:19:19
Django version 1.11.15, using settings 'Access.settings'
Starting development server at http://127.0.0.1:8000/
Quit the server with CTRL-BREAK.
^C
(venv) F:\Django\Access>python manage.py makemigrations
No changes detected

(venv) F:\Django\Access>python manage.py migrate
Operations to perform:
  Apply all migrations: admin, auth, contenttypes, rbac, sessions
Running migrations:
  Applying rbac.0002_auto_20181107_1214...Traceback (most recent call last):
  File "F:\venv\lib\site-packages\django\db\backends\utils.py", line 62, in execute
    return self.cursor.execute(sql)
  File "F:\venv\lib\site-packages\django\db\backends\sqlite3\base.py", line 326, in execute
    return Database.Cursor.execute(self, query)
sqlite3.OperationalError: table "rbac_permission_permissionRole" already exists

The above exception was the direct cause of the following exception:

Traceback (most recent call last):
  File "manage.py", line 22, in <module>
    execute_from_command_line(sys.argv)
  File "F:\venv\lib\site-packages\django\core\management\__init__.py", line 364, in execute_from_command_line
    utility.execute()
  File "F:\venv\lib\site-packages\django\core\management\__init__.py", line 356, in execute
    self.fetch_command(subcommand).run_from_argv(self.argv)
  File "F:\venv\lib\site-packages\django\core\management\base.py", line 283, in run_from_argv
    self.execute(*args, **cmd_options)
  File "F:\venv\lib\site-packages\django\core\management\base.py", line 330, in execute
    output = self.handle(*args, **options)
  File "F:\venv\lib\site-packages\django\core\management\commands\migrate.py", line 204, in handle
    fake_initial=fake_initial,
  File "F:\venv\lib\site-packages\django\db\migrations\executor.py", line 115, in migrate
    state = self._migrate_all_forwards(state, plan, full_plan, fake=fake, fake_initial=fake_initial)
  File "F:\venv\lib\site-packages\django\db\migrations\executor.py", line 145, in _migrate_all_forwards
    state = self.apply_migration(state, migration, fake=fake, fake_initial=fake_initial)
  File "F:\venv\lib\site-packages\django\db\migrations\executor.py", line 244, in apply_migration
    state = migration.apply(state, schema_editor)
  File "F:\venv\lib\site-packages\django\db\migrations\migration.py", line 129, in apply
    operation.database_forwards(self.app_label, schema_editor, old_state, project_state)
  File "F:\venv\lib\site-packages\django\db\migrations\operations\fields.py", line 311, in database_forwards
    to_model._meta.get_field(self.new_name),
  File "F:\venv\lib\site-packages\django\db\backends\base\schema.py", line 516, in alter_field
    return self._alter_many_to_many(model, old_field, new_field, strict)
  File "F:\venv\lib\site-packages\django\db\backends\sqlite3\schema.py", line 282, in _alter_many_to_many
    self.create_model(new_field.remote_field.through)
  File "F:\venv\lib\site-packages\django\db\backends\base\schema.py", line 319, in create_model
    self.execute(sql, params or None)
  File "F:\venv\lib\site-packages\django\db\backends\base\schema.py", line 136, in execute
    cursor.execute(sql, params)
  File "F:\venv\lib\site-packages\django\db\backends\utils.py", line 79, in execute
    return super(CursorDebugWrapper, self).execute(sql, params)
  File "F:\venv\lib\site-packages\django\db\backends\utils.py", line 64, in execute
    return self.cursor.execute(sql, params)
  File "F:\venv\lib\site-packages\django\db\utils.py", line 94, in __exit__
    six.reraise(dj_exc_type, dj_exc_value, traceback)
  File "F:\venv\lib\site-packages\django\utils\six.py", line 685, in reraise
    raise value.with_traceback(tb)
  File "F:\venv\lib\site-packages\django\db\backends\utils.py", line 62, in execute
    return self.cursor.execute(sql)
  File "F:\venv\lib\site-packages\django\db\backends\sqlite3\base.py", line 326, in execute
    return Database.Cursor.execute(self, query)
django.db.utils.OperationalError: table "rbac_permission_permissionRole" already exists
```